name: run
run_id: commands[0]
env TERM: xterm-256color
env TMPDIR: /var/folders/d_/fmwppt2s6zdd3hc8y4fvs_km0000gn/T/
env LANG: en_US.UTF-8
env HOME: /Users/albertmends
env PATH: /Users/albertmends/Documents/ecoair/backend/.tox/test_app/bin:/Library/Frameworks/Python.framework/Versions/3.12/bin:/Users/albertmends/.nvm/versions/node/v21.2.0/bin:/opt/homebrew/bin:/opt/homebrew/sbin:/usr/local/bin:/System/Cryptexes/App/usr/bin:/usr/bin:/bin:/usr/sbin:/sbin:/var/run/com.apple.security.cryptexd/codex.system/bootstrap/usr/local/bin:/var/run/com.apple.security.cryptexd/codex.system/bootstrap/usr/bin:/var/run/com.apple.security.cryptexd/codex.system/bootstrap/usr/appleinternal/bin:/Library/Apple/usr/bin
env PYTHONHASHSEED: 4141979601
env PIP_DISABLE_PIP_VERSION_CHECK: 1
env PYTHONIOENCODING: utf-8
env PYTHONPATH: .
env TOX_ENV_NAME: run
env TOX_WORK_DIR: /Users/albertmends/Documents/ecoair/backend/.tox
env TOX_ENV_DIR: /Users/albertmends/Documents/ecoair/backend/.tox/test_app
env VIRTUAL_ENV: /Users/albertmends/Documents/ecoair/backend/.tox/test_app
env COLUMNS: 59
env LINES: 9
metadata pid: 36264
cwd: /Users/albertmends/Documents/ecoair/backend
allow: /Users/albertmends/Documents/ecoair/backend/.tox/test_app/bin/*
cmd: python app/main.py
exit_code: -2
[32mINFO[0m:     ::1:56186 - "[1mGET /docs HTTP/1.1[0m" [32m200 OK[0m
[32mINFO[0m:     ::1:56188 - "[1mGET /api/v1/openapi.json HTTP/1.1[0m" [32m200 OK[0m
[32mINFO[0m:     ::1:56188 - "[1mGET /api/v1/locations/fetch_locations HTTP/1.1[0m" [91m500 Internal Server Error[0m

standard error:
[32m2024-03-21 12:23:11.545[0m | [33m[1mWARNING [0m | [36m__main__[0m:[36m<module>[0m:[36m60[0m - [33m[1mRunning in development mode. Do not run like this in production.[0m
[32mINFO[0m:     Started server process [[36m36264[0m]
[32mINFO[0m:     Waiting for application startup.
[32mINFO[0m:     Application startup complete.
[32mINFO[0m:     Uvicorn running on [1mhttp://localhost:8001[0m (Press CTRL+C to quit)
[31mERROR[0m:    Exception in ASGI application
Traceback (most recent call last):
  File "/Users/albertmends/Documents/ecoair/backend/.tox/test_app/lib/python3.11/site-packages/uvicorn/protocols/http/h11_impl.py", line 407, in run_asgi
    result = await app(  # type: ignore[func-returns-value]
             ^^^^^^^^^^^^^^^^^^^^^^^^^^^^^^^^^^^^^^^^^^^^^^
  File "/Users/albertmends/Documents/ecoair/backend/.tox/test_app/lib/python3.11/site-packages/uvicorn/middleware/proxy_headers.py", line 69, in __call__
    return await self.app(scope, receive, send)
           ^^^^^^^^^^^^^^^^^^^^^^^^^^^^^^^^^^^^
  File "/Users/albertmends/Documents/ecoair/backend/.tox/test_app/lib/python3.11/site-packages/fastapi/applications.py", line 1054, in __call__
    await super().__call__(scope, receive, send)
  File "/Users/albertmends/Documents/ecoair/backend/.tox/test_app/lib/python3.11/site-packages/starlette/applications.py", line 123, in __call__
    await self.middleware_stack(scope, receive, send)
  File "/Users/albertmends/Documents/ecoair/backend/.tox/test_app/lib/python3.11/site-packages/starlette/middleware/errors.py", line 186, in __call__
    raise exc
  File "/Users/albertmends/Documents/ecoair/backend/.tox/test_app/lib/python3.11/site-packages/starlette/middleware/errors.py", line 164, in __call__
    await self.app(scope, receive, _send)
  File "/Users/albertmends/Documents/ecoair/backend/.tox/test_app/lib/python3.11/site-packages/starlette/middleware/cors.py", line 83, in __call__
    await self.app(scope, receive, send)
  File "/Users/albertmends/Documents/ecoair/backend/.tox/test_app/lib/python3.11/site-packages/starlette/middleware/exceptions.py", line 62, in __call__
    await wrap_app_handling_exceptions(self.app, conn)(scope, receive, send)
  File "/Users/albertmends/Documents/ecoair/backend/.tox/test_app/lib/python3.11/site-packages/starlette/_exception_handler.py", line 64, in wrapped_app
    raise exc
  File "/Users/albertmends/Documents/ecoair/backend/.tox/test_app/lib/python3.11/site-packages/starlette/_exception_handler.py", line 53, in wrapped_app
    await app(scope, receive, sender)
  File "/Users/albertmends/Documents/ecoair/backend/.tox/test_app/lib/python3.11/site-packages/starlette/routing.py", line 758, in __call__
    await self.middleware_stack(scope, receive, send)
  File "/Users/albertmends/Documents/ecoair/backend/.tox/test_app/lib/python3.11/site-packages/starlette/routing.py", line 778, in app
    await route.handle(scope, receive, send)
  File "/Users/albertmends/Documents/ecoair/backend/.tox/test_app/lib/python3.11/site-packages/starlette/routing.py", line 299, in handle
    await self.app(scope, receive, send)
  File "/Users/albertmends/Documents/ecoair/backend/.tox/test_app/lib/python3.11/site-packages/starlette/routing.py", line 79, in app
    await wrap_app_handling_exceptions(app, request)(scope, receive, send)
  File "/Users/albertmends/Documents/ecoair/backend/.tox/test_app/lib/python3.11/site-packages/starlette/_exception_handler.py", line 64, in wrapped_app
    raise exc
  File "/Users/albertmends/Documents/ecoair/backend/.tox/test_app/lib/python3.11/site-packages/starlette/_exception_handler.py", line 53, in wrapped_app
    await app(scope, receive, sender)
  File "/Users/albertmends/Documents/ecoair/backend/.tox/test_app/lib/python3.11/site-packages/starlette/routing.py", line 74, in app
    response = await func(request)
               ^^^^^^^^^^^^^^^^^^^
  File "/Users/albertmends/Documents/ecoair/backend/.tox/test_app/lib/python3.11/site-packages/fastapi/routing.py", line 296, in app
    content = await serialize_response(
              ^^^^^^^^^^^^^^^^^^^^^^^^^
  File "/Users/albertmends/Documents/ecoair/backend/.tox/test_app/lib/python3.11/site-packages/fastapi/routing.py", line 155, in serialize_response
    raise ResponseValidationError(
fastapi.exceptions.ResponseValidationError: 1 validation errors:
  {'loc': ('response', 'results'), 'msg': 'field required', 'type': 'value_error.missing'}

[32mINFO[0m:     Shutting down
[32mINFO[0m:     Finished server process [[36m36264[0m]
[31mERROR[0m:    Traceback (most recent call last):
  File "/opt/homebrew/Cellar/python@3.11/3.11.6_1/Frameworks/Python.framework/Versions/3.11/lib/python3.11/asyncio/runners.py", line 190, in run
    return runner.run(main)
           ^^^^^^^^^^^^^^^^
  File "/opt/homebrew/Cellar/python@3.11/3.11.6_1/Frameworks/Python.framework/Versions/3.11/lib/python3.11/asyncio/runners.py", line 118, in run
    return self._loop.run_until_complete(task)
           ^^^^^^^^^^^^^^^^^^^^^^^^^^^^^^^^^^^
  File "/opt/homebrew/Cellar/python@3.11/3.11.6_1/Frameworks/Python.framework/Versions/3.11/lib/python3.11/asyncio/base_events.py", line 640, in run_until_complete
    self.run_forever()
  File "/opt/homebrew/Cellar/python@3.11/3.11.6_1/Frameworks/Python.framework/Versions/3.11/lib/python3.11/asyncio/base_events.py", line 607, in run_forever
    self._run_once()
  File "/opt/homebrew/Cellar/python@3.11/3.11.6_1/Frameworks/Python.framework/Versions/3.11/lib/python3.11/asyncio/base_events.py", line 1922, in _run_once
    handle._run()
  File "/opt/homebrew/Cellar/python@3.11/3.11.6_1/Frameworks/Python.framework/Versions/3.11/lib/python3.11/asyncio/events.py", line 80, in _run
    self._context.run(self._callback, *self._args)
  File "/Users/albertmends/Documents/ecoair/backend/.tox/test_app/lib/python3.11/site-packages/uvicorn/server.py", line 68, in serve
    with self.capture_signals():
  File "/opt/homebrew/Cellar/python@3.11/3.11.6_1/Frameworks/Python.framework/Versions/3.11/lib/python3.11/contextlib.py", line 144, in __exit__
    next(self.gen)
  File "/Users/albertmends/Documents/ecoair/backend/.tox/test_app/lib/python3.11/site-packages/uvicorn/server.py", line 328, in capture_signals
    signal.raise_signal(captured_signal)
  File "/opt/homebrew/Cellar/python@3.11/3.11.6_1/Frameworks/Python.framework/Versions/3.11/lib/python3.11/asyncio/runners.py", line 157, in _on_sigint
    raise KeyboardInterrupt()
KeyboardInterrupt

During handling of the above exception, another exception occurred:

Traceback (most recent call last):
  File "/Users/albertmends/Documents/ecoair/backend/.tox/test_app/lib/python3.11/site-packages/starlette/routing.py", line 743, in lifespan
    await receive()
  File "/Users/albertmends/Documents/ecoair/backend/.tox/test_app/lib/python3.11/site-packages/uvicorn/lifespan/on.py", line 137, in receive
    return await self.receive_queue.get()
           ^^^^^^^^^^^^^^^^^^^^^^^^^^^^^^
  File "/opt/homebrew/Cellar/python@3.11/3.11.6_1/Frameworks/Python.framework/Versions/3.11/lib/python3.11/asyncio/queues.py", line 158, in get
    await getter
asyncio.exceptions.CancelledError

Traceback (most recent call last):
  File "/Users/albertmends/Documents/ecoair/backend/app/main.py", line 63, in <module>
    uvicorn.run(app, host="localhost", port=8001, log_level="debug")
  File "/Users/albertmends/Documents/ecoair/backend/.tox/test_app/lib/python3.11/site-packages/uvicorn/main.py", line 575, in run
    server.run()
  File "/Users/albertmends/Documents/ecoair/backend/.tox/test_app/lib/python3.11/site-packages/uvicorn/server.py", line 65, in run
    return asyncio.run(self.serve(sockets=sockets))
           ^^^^^^^^^^^^^^^^^^^^^^^^^^^^^^^^^^^^^^^^
  File "/opt/homebrew/Cellar/python@3.11/3.11.6_1/Frameworks/Python.framework/Versions/3.11/lib/python3.11/asyncio/runners.py", line 190, in run
    return runner.run(main)
           ^^^^^^^^^^^^^^^^
  File "/opt/homebrew/Cellar/python@3.11/3.11.6_1/Frameworks/Python.framework/Versions/3.11/lib/python3.11/asyncio/runners.py", line 118, in run
    return self._loop.run_until_complete(task)
           ^^^^^^^^^^^^^^^^^^^^^^^^^^^^^^^^^^^
  File "/opt/homebrew/Cellar/python@3.11/3.11.6_1/Frameworks/Python.framework/Versions/3.11/lib/python3.11/asyncio/base_events.py", line 640, in run_until_complete
    self.run_forever()
  File "/opt/homebrew/Cellar/python@3.11/3.11.6_1/Frameworks/Python.framework/Versions/3.11/lib/python3.11/asyncio/base_events.py", line 607, in run_forever
    self._run_once()
  File "/opt/homebrew/Cellar/python@3.11/3.11.6_1/Frameworks/Python.framework/Versions/3.11/lib/python3.11/asyncio/base_events.py", line 1922, in _run_once
    handle._run()
  File "/opt/homebrew/Cellar/python@3.11/3.11.6_1/Frameworks/Python.framework/Versions/3.11/lib/python3.11/asyncio/events.py", line 80, in _run
    self._context.run(self._callback, *self._args)
  File "/Users/albertmends/Documents/ecoair/backend/.tox/test_app/lib/python3.11/site-packages/uvicorn/server.py", line 68, in serve
    with self.capture_signals():
  File "/opt/homebrew/Cellar/python@3.11/3.11.6_1/Frameworks/Python.framework/Versions/3.11/lib/python3.11/contextlib.py", line 144, in __exit__
    next(self.gen)
  File "/Users/albertmends/Documents/ecoair/backend/.tox/test_app/lib/python3.11/site-packages/uvicorn/server.py", line 328, in capture_signals
    signal.raise_signal(captured_signal)
  File "/opt/homebrew/Cellar/python@3.11/3.11.6_1/Frameworks/Python.framework/Versions/3.11/lib/python3.11/asyncio/runners.py", line 157, in _on_sigint
    raise KeyboardInterrupt()
KeyboardInterrupt
