name: run
run_id: commands[0]
env TERM: xterm-256color
env TMPDIR: /var/folders/d_/fmwppt2s6zdd3hc8y4fvs_km0000gn/T/
env LANG: en_US.UTF-8
env HOME: /Users/albertmends
env PATH: /Users/albertmends/Documents/ecoair/backend/.tox/test_app/bin:/Library/Frameworks/Python.framework/Versions/3.12/bin:/Users/albertmends/.nvm/versions/node/v21.2.0/bin:/opt/homebrew/bin:/opt/homebrew/sbin:/usr/local/bin:/System/Cryptexes/App/usr/bin:/usr/bin:/bin:/usr/sbin:/sbin:/var/run/com.apple.security.cryptexd/codex.system/bootstrap/usr/local/bin:/var/run/com.apple.security.cryptexd/codex.system/bootstrap/usr/bin:/var/run/com.apple.security.cryptexd/codex.system/bootstrap/usr/appleinternal/bin:/Library/Apple/usr/bin
env PYTHONHASHSEED: 803781329
env PIP_DISABLE_PIP_VERSION_CHECK: 1
env PYTHONIOENCODING: utf-8
env PYTHONPATH: .
env TOX_ENV_NAME: run
env TOX_WORK_DIR: /Users/albertmends/Documents/ecoair/backend/.tox
env TOX_ENV_DIR: /Users/albertmends/Documents/ecoair/backend/.tox/test_app
env VIRTUAL_ENV: /Users/albertmends/Documents/ecoair/backend/.tox/test_app
env COLUMNS: 59
env LINES: 6
metadata pid: 38260
cwd: /Users/albertmends/Documents/ecoair/backend
allow: /Users/albertmends/Documents/ecoair/backend/.tox/test_app/bin/*
cmd: python app/main.py
exit_code: 1

standard error:
Traceback (most recent call last):
  File "pydantic/config.py", line 189, in pydantic.config.prepare_config
  File "/opt/homebrew/Cellar/python@3.11/3.11.6_1/Frameworks/Python.framework/Versions/3.11/lib/python3.11/enum.py", line 712, in __call__
    return cls.__new__(cls, value)
           ^^^^^^^^^^^^^^^^^^^^^^^
  File "/opt/homebrew/Cellar/python@3.11/3.11.6_1/Frameworks/Python.framework/Versions/3.11/lib/python3.11/enum.py", line 1135, in __new__
    raise ve_exc
ValueError: True is not a valid Extra

During handling of the above exception, another exception occurred:

Traceback (most recent call last):
  File "/Users/albertmends/Documents/ecoair/backend/app/main.py", line 13, in <module>
    from app.api.api_router import api_router
  File "/Users/albertmends/Documents/ecoair/backend/app/api/api_router.py", line 3, in <module>
    from .endpoints.countries import router as countries_router
  File "/Users/albertmends/Documents/ecoair/backend/app/api/endpoints/countries.py", line 5, in <module>
    from app import __version__, schemas
  File "/Users/albertmends/Documents/ecoair/backend/app/schemas/__init__.py", line 4, in <module>
    from .locations import LocationResponse
  File "/Users/albertmends/Documents/ecoair/backend/app/schemas/locations.py", line 34, in <module>
    class Location(BaseModel):
  File "pydantic/main.py", line 170, in pydantic.main.ModelMetaclass.__new__
  File "pydantic/config.py", line 191, in pydantic.config.prepare_config
ValueError: "Location": True is not a valid value for "extra"
